Workbook

Sheet Sheet1
A3: Row Labels | B3: Sum of Amount
A4: Travel | B4: 712100
A5: Food | B5: 683131
A6: Entertainment | B6: 661907
A7: Transport | B7: 634722
A8: Rent | B8: 630661
A9: Grand Total | B9: 3322521
A23: Row Labels | B23: Sum of Amount
A24: January | B24: 509483
A25: February | B25: 428282
A26: March | B26: 472054
A27: April | B27: 451199
A28: May | B28: 468676
A29: June | B29: 432750
A30: July | B30: 433585
A31: August | B31: 472483
A32: September | B32: 480003
A33: October | B33: 564334
A34: November | B34: 455804
A35: December | B35: 504653
A36: Grand Total | B36: 5673306
A43: Row Labels | B43: Sum of Amount
A44: Variable | B44: 3788037
A45: Fixed | B45: 1885269
A46: Grand Total | B46: 5673306
A60: Row Labels | B60: Sum of Amount
A61: online | B61: 4558857
A62: offline | B62: 1114449
A63: Grand Total | B63: 5673306
A78: Row Labels | B78: Sum of Amount | C78: Max of Monthly budget
A79: Rent | B79: 630661 | C79: 5500
A80: Travel | B80: 712100 | C80: 5000
A81: Transport | B81: 634722 | C81: 4000
A82: Food | B82: 683131 | C82: 3000
A83: Entertainment | B83: 661907 | C83: 1000
A84: Grand Total | B84: 3322521 | C84: 5500
A94: Row Labels | B94: Sum of Amount
A95: Travel | B95: 712100
A96: within budget | B96: 712100
A97: Food | B97: 683131
...

Sheet Expense_Tracker_2000_Plus_Data
A1: Date | B1: Month | C1: Category | D1: Description | E1: Payment Mode | F1: Amount | G1: Expense type | H1: Payment type | I1: Month no. | J1: Monthly budget | K1: budget status
A2: 45580 | B2: October | C2: Bills | D2: Train ticket | E2: Debit Card | F2: 4220 | G2: =VLOOKUP(C2,Sheet2!$C$3:$D$12,2,0) -> Fixed | H2: =IFERROR(VLOOKUP(E2,Sheet2!$G$3:$H$8,2,0),"unkwon") -> online | I2: =VLOOKUP(B2,Sheet2!$J$4:$K$15,2,0) -> 10 | J2: =IFERROR(VLOOKUP(C2,Sheet2!$M$4:$N$12,2,0),0) -> 2000 | K2: =IF(F2>J2,"over budget","within budget") -> over budget
A3: 45230 | B3: October | C3: Health | D3: College fees | E3: Credit Card | F3: 2802 | G3: =VLOOKUP(C3,Sheet2!$C$3:$D$12,2,0) -> Variable | H3: =IFERROR(VLOOKUP(E3,Sheet2!$G$3:$H$8,2,0),"unkwon") -> online | I3: =VLOOKUP(B3,Sheet2!$J$4:$K$15,2,0) -> 10 | J3: =IFERROR(VLOOKUP(C3,Sheet2!$M$4:$N$12,2,0),0) -> 5000 | K3: =IF(F3>J3,"over budget","within budget") -> within budget
A4: 45569 | B4: October | C4: Travel | D4: Online shopping | E4: UPI | F4: 1152 | G4: =VLOOKUP(C4,Sheet2!$C$3:$D$12,2,0) -> Variable | H4: =IFERROR(VLOOKUP(E4,Sheet2!$G$3:$H$8,2,0),"unkwon") -> online | I4: =VLOOKUP(B4,Sheet2!$J$4:$K$15,2,0) -> 10 | J4: =IFERROR(VLOOKUP(C4,Sheet2!$M$4:$N$12,2,0),0) -> 5000 | K4: =IF(F4>J4,"over budget","within budget") -> within budget
A5: 45277 | B5: December | C5: Bills | D5: College fees | E5: Net Banking | F5: 2439 | G5: =VLOOKUP(C5,Sheet2!$C$3:$D$12,2,0) -> Fixed | H5: =IFERROR(VLOOKUP(E5,Sheet2!$G$3:$H$8,2,0),"unkwon") -> online | I5: =VLOOKUP(B5,Sheet2!$J$4:$K$15,2,0) -> 12 | J5: =IFERROR(VLOOKUP(C5,Sheet2!$M$4:$N$12,2,0),0) -> 2000 | K5: =IF(F5>J5,"over budget","within budget") -> over budget
A6: 45589 | B6: October | C6: Bills | D6: Bus fare | E6: Debit Card | F6: 688 | G6: =VLOOKUP(C6,Sheet2!$C$3:$D$12,2,0) -> Fixed | H6: =IFERROR(VLOOKUP(E6,Sheet2!$G$3:$H$8,2,0),"unkwon") -> online | I6: =VLOOKUP(B6,Sheet2!$J$4:$K$15,2,0) -> 10 | J6: =IFERROR(VLOOKUP(C6,Sheet2!$M$4:$N$12,2,0),0) -> 2000 | K6: =IF(F6>J6,"over budget","within budget") -> within budget
A7: 45352 | B7: March | C7: Health | D7: Medical checkup | E7: Net Banking | F7: 3983 | G7: =VLOOKUP(C7,Sheet2!$C$3:$D$12,2,0) -> Variable | H7: =IFERROR(VLOOKUP(E7,Sheet2!$G$3:$H$8,2,0),"unkwon") -> online | I7: =VLOOKUP(B7,Sheet2!$J$4:$K$15,2,0) -> 3 | J7: =IFERROR(VLOOKUP(C7,Sheet2!$M$4:$N$12,2,0),0) -> 5000 | K7: =IF(F7>J7,"over budget","within budget") -> within budget
A8: 45129 | B8: July | C8: Entertainment | D8: Movie ticket | E8: UPI | F8: 3627 | G8: =VLOOKUP(C8,Sheet2!$C$3:$D$12,2,0) -> Variable | H8: =IFERROR(VLOOKUP(E8,Sheet2!$G$3:$H$8,2,0),"unkwon") -> online | I8: =VLOOKUP(B8,Sheet2!$J$4:$K$15,2,0) -> 7 | J8: =IFERROR(VLOOKUP(C8,Sheet2!$M$4:$N$12,2,0),0) -> 1000 | K8: =IF(F8>J8,"over budget","within budget") -> over budget
A9: 45627 | B9: December | C9: Entertainment | D9: Monthly rent | E9: Debit Card | F9: 2039 | G9: =VLOOKUP(C9,Sheet2!$C$3:$D$12,2,0) -> Variable | H9: =IFERROR(VLOOKUP(E9,Sheet2!$G$3:$H$8,2,0),"unkwon") -> online | I9: =VLOOKUP(B9,Sheet2!$J$4:$K$15,2,0) -> 12 | J9: =IFERROR(VLOOKUP(C9,Sheet2!$M$4:$N$12,2,0),0) -> 1000 | K9: =IF(F9>J9,"over budget","within budget") -> over budget
A10: 45166 | B10: August | C10: Health | D10: Electricity bill | E10: Credit Card | F10: 3822 | G10: =VLOOKUP(C10,Sheet2!$C$3:$D$12,2,0) -> Variable | H10: =IFERROR(VLOOKUP(E10,Sheet2!$G$3:$H$8,2,0),"unkwon") -> online | I10: =VLOOKUP(B10,Sheet2!$J$4:$K$15,2,0) -> 8 | J10: =IFERROR(VLOOKUP(C10,Sheet2!$M$4:$N$12,2,0),0) -> 5000 | K10: =IF(F10>J10,"over budget","within budget") -> within budget
A11: 45510 | B11: August | C11: Transport | D11: Online shopping | E11: UPI | F11: 3506 | G11: =VLOOKUP(C11,Sheet2!$C$3:$D$12,2,0) -> Variable | H11: =IFERROR(VLOOKUP(E11,Sheet2!$G$3:$H$8,2,0),"unkwon") -> online | I11: =VLOOKUP(B11,Sheet2!$J$4:$K$15,2,0) -> 8 | J11: =IFERROR(VLOOKUP(C11,Sheet2!$M$4:$N$12,2,0),0) -> 4000 | K11: =IF(F11>J11,"over budget","within budget") -> within budget
A12: 45440 | B12: May | C12: Transport | D12: Electricity bill | E12: UPI | F12: 3468 | G12: =VLOOKUP(C12,Sheet2!$C$3:$D$12,2,0) -> Variable | H12: =IFERROR(VLOOKUP(E12,Sheet2!$G$3:$H$8,2,0),"unkwon") -> online | I12: =VLOOKUP(B12,Sheet2!$J$4:$K$15,2,0) -> 5 | J12: =IFERROR(VLOOKUP(C12,Sheet2!$M$4:$N$12,2,0),0) -> 4000 | K12: =IF(F12>J12,"over budget","within budget") -> within budget
A13: 45402 | B13: April | C13: Food | D13: Online shopping | E13: Credit Card | F13: 1669 | G13: =VLOOKUP(C13,Sheet2!$C$3:$D$12,2,0) -> Fixed | H13: =IFERROR(VLOOKUP(E13,Sheet2!$G$3:$H$8,2,0),"unkwon") -> online | I13: =VLOOKUP(B13,Sheet2!$J$4:$K$15,2,0) -> 4 | J13: =IFERROR(VLOOKUP(C13,Sheet2!$M$4:$N$12,2,0),0) -> 3000 | K13: =IF(F13>J13,"over budget","within budget") -> within budget
... A2201: 45195 | B2201: September | C2201: Transport | D2201: Electricity bill | E2201: Debit Card | F2201: 4898 | G2201: =VLOOKUP(C2201,Sheet2!$C$3:$D$12,2,0) -> Variable | H2201: =IFERROR(VLOOKUP(E2201,Sheet2!$G$3:$H$8,2,0),"unkwon") -> online | I2201: =VLOOKUP(B2201,Sheet2!$J$4:$K$15,2,0) -> 9 | J2201: =IFERROR(VLOOKUP(C2201,Sheet2!$M$4:$N$12,2,0),0) -> 4000 | K2201: =IF(F2201>J2201,"over budget","within budget") -> over budget

Sheet Sheet2
C3: Categeroy | D3: Expense type | G3: Payment mode | H3: payment type | J3: month name | K3: month no. | M3: Categeroy | N3: monthly budget
C4: {=_xlfn.UNIQUE(Expense_Tracker_2000_Plus_Data!$C$2:$C$2201)} -> Bills | D4: Fixed | G4: {=_xlfn.UNIQUE(Expense_Tracker_2000_Plus_Data!E2:E2201)} -> Debit Card | H4: online | J4: january | K4: 1 | M4: {=_xlfn.UNIQUE(Expense_Tracker_2000_Plus_Data!$C$2:$C$2201)} -> Bills | N4: 2000
C5: Health | D5: Variable | G5: Credit Card | H5: online | J5: february | K5: 2 | M5: Health | N5: 5000
C6: Travel | D6: Variable | G6: UPI | H6: online | J6: march | K6: 3 | M6: Travel | N6: 5000
C7: Entertainment | D7: Variable | G7: Net Banking | H7: online | J7: april | K7: 4 | M7: Entertainment | N7: 1000
C8: Transport | D8: Variable | G8: Cash | H8: offline | J8: may | K8: 5 | M8: Transport | N8: 4000
C9: Food | D9: Fixed | J9: june | K9: 6 | M9: Food | N9: 3000
C10: Rent | D10: Fixed | J10: july | K10: 7 | M10: Rent | N10: 5500
C11: Shopping | D11: Variable | J11: august | K11: 8 | M11: Shopping | N11: 10000
C12: Education | D12: Variable | J12: september | K12: 9 | M12: Education | N12: 7000
J13: october | K13: 10
J14: november | K14: 11
J15: december | K15: 12
